Workbook

Sheet Sheet1
A1: AIAA RFP GIVEN VALUES
A3: Section # | B3: Item | C3: # Of Item | D3: Item Weight (each) | E3: Total Weight (lbs) | H3: Section # | I3: Item | J3: # Of Item | K3: Item Weight (each) | L3: Total Weight (lbs)
A4: 3.3.1 | B4: Avionics/Sensors Weight, A2A | C4: 1 | D4: 2500 | E4: =D4*C4 -> 2500 | H4: 3.3.2 | I4: Avionics/Sensors Weight, STRIKE | J4: 1 | K4: 2500 | L4: =K4*J4 -> 2500
A5: 3.3.1 | B5: Ordnance Load, AIM-120C, A2A | C5: 6 | D5: 348 | E5: =D5*C5 -> 2088 | H5: 3.3.2 | I5: Ordnance Load, MK-83 JDAM, STRIKE | J5: 4 | K5: 1000 | L5: =K5*J5 -> 4000
A6: 3.3.1 | B6: Ordnance Load, AIM-9X, A2A | C6: 2 | D6: 186 | E6: =D6*C6 -> 372 | H6: 3.3.2 | I6: Ordnance Load, AIM-9X, STRIKE | J6: 2 | K6: 186 | L6: =K6*J6 -> 372

Sheet Wing_Area_Sizing_(BEN)
A1: BEN
A2: Wing Area Sizing | F2: Mach | G2: Vmax (ft/s) | I2: Altitude (ft) | J2: Air Density (slug/ft^3) | L2: Thrust | M2: Weight | N2: k | O2: CD0 | P2: S (ft^2)
F3: 2.12 | G3: 2049 | I3: 45000 | J3: 0.000462 | L3: 35400 | M3: 33429 | N3: 0.06 | O3: 0.11313 | P3: 600
A4: W0 | B4: Initial Weight | C4: 230000 | F4: 1.88 | G4: 1818 | I4: 40000 | J4: 0.000587
A5: Wf | B5: Final Weight | C5: 115000 | F5: 1.7 | G5: 1650 | I5: 36000 | J5: 0.000713
A6: ρ | B6: Air Density | C6: 0.432 | F6: 1.49 | G6: 1476 | I6: 30000 | J6: 0.000891
A7: k | B7: Induced drag parameter | C7: =1/(C8*C9*C10) -> 0.095781229 | F7: 1.08 | G7: 1137 | I7: 15000 | J7: 0.001496
A8: π | B8: Pi | C8: 3.14159 | F8: 0.81 | G8: 903 | I8: 0 | J8: 0.002377
A9: A | B9: Aspect Ratio | C9: =WingLayout!F6 -> 4.4310722
A10: e | B10: Oswalk Efficiency | C10: 0.75
A11: Cd0 | B11: Zero Lift Drag Coefficient | C11: 0.0264
A12: Emax | B12: Maximum Efficiency | C12: =(0.5*SQRT(1/(C7*C11))) -> 9.9432381
A13: c | B13: Specific Fuel Consumption | C13: =0.000023 * 9.81 -> 0.00022563

Sheet Structural Weight-MatProperties
A1: Parameter | B1: Symbol | C1: Units | D1: Value | G1: OUTPUTS
A2: GLOBAL
A3: Takeoff Weight | B3: W_TO | C3: lb | D3: ='IGNORE THIS PAGE'!F11 -> 50012.357 | G3: Wing Weight (lb) – Roskam USN Eq. 5.10
A4: Ultimate load factor | B4: n_ult | C4: - | D4: 9 | G4: =19.29*((((D12*D4*D3)/(D9))*(((TAN(D11))-((2*(1-D10))/(D8*(1+D10))))^2+1)*10^-6))^(0.464)*((1+D10)*D8)^(0.7)*D7^0.58 -> 5200.2921
A6: WING INPUTS | G6: Horizontal Tail Weight (lb) – Roskam Eq. 5.17
A7: Wing area | B7: S_w | C7: ft^2 | D7: =WingLayout!C6 -> 457 | G7: =0.0034*((D3*D4)^(0.813)*D15^(0.584)*(D16/(WingLayout!F32*0.1))^(0.033)*(D18/WingLayout!C35)^(0.28))^0.915 -> 558.65129
A8: Aspect ratio | B8: A | C8: - | D8: =WingLayout!F6 -> 4.4310722
A9: Mean t/c | B9: (t/c)_m | C9: - | D9: 0.1 | G9: Vertical Tail Weight (lb) – Roskam Eq. 5.18
A10: Taper ratio | B10: λ_w | C10: - | D10: =WingLayout!C8 -> 0.5 | G10: =0.19*((1+D26)^0.5)*((D3*D4)^0.363)*(D23^1.089)*(D27^0.601)*((D28)^-0.726)*((1+D29)^0.217)*(D24^0.337)*((1+D25)^0.363)*(COS(RADIANS(D30))^-0.484)*1.014 -> 1476.4888
A11: LE sweep | B11: Λ_LE | C11: RAD | D11: =WingLayout!C9*(PI()/180) -> 0.34906585
A12: Material factor | B12: K_w | C12: - | D12: 1 | G12: Fuselage Weight (lb) – Roskam USN Eq. 5.28 (GD method)
G13: #DIV/0!
A14: HORIZONTAL TAIL INPUTS
A15: Tail area | B15: S_h | C15: ft^2 | D15: =WingLayout!C30 -> 110 | G15: Structure subtotal (Wing + H + V + Fuselage) (lb) | Q15: TSFC | R15: L/D | S15: Wi/Wf | T15: V | U15: Range
A16: Tail span | B16: b_h | C16: ft | D16: =WingLayout!C31 -> 19 | G16: =G4+G7+G10 -> 7235.4322 | Q16: 0.8 | R16: 7.7 | S16: =1/0.73 -> 1.369863 | T16: 530 | U16: =(T16/Q16)*(R16)*LN(S16) -> 1605.4182
A17: Root t/c | B17: t_rh | C17: - | D17: 0.1
A18: Tail MAC | B18: c_bar_h | C18: in | D18: =WingLayout!F35 -> 72.046784
A19: Tail arm (wing 1/4c -> H 1/4c) | B19: l_h | C19: in | D19: =WingLayout!C35 -> 216.96
A20: Taper ratio (H) | B20: λ_h | C20: - | D20: =WingLayout!C32 -> 0.5
A22: VERTICAL TAIL INPUTS
A23: Vertical tail area | B23: S_v | C23: ft^2 | D23: =WingLayout!$C$61 -> 100
A24: Aspect ratio (V) | B24: A_v | C24: - | D24: =WingLayout!$F$62 -> 5.12
A25: Taper ratio (V) | B25: λ_v | C25: - | D25: =WingLayout!$C$64 -> 0.5
A26: z_h / b_v | B26: z_h/b_v | C26: - | D26: 0 | E26: (FOR V-TAIL MOUNTED ON FUSELAGE, Z_H = 0)
A27: M_H (Roskam 5.18) | B27: M_H | C27: - | D27: 1.6
A28: Tail arm (V) | B28: l_v | C28: ft | D28: =WingLayout!C69 -> 15.75
A29: Rudder area ratio | B29: S_r/S_v | C29: - | D29: 0.3
A30: Quarter-chord sweep (V) | B30: Λ_1/4,v | C30: deg | D30: =WingLayout!C70 -> 45.085193
A32: FUSELAGE INPUTS (USN GD method) | G32: q_d Calculation | J32: Value
A33: Inlet factor | B33: K_inl | C33: - | D33: 1.25 | G33: Density (Sea Level) | I33: ρ | J33: 0.002377
A34: Dynamic Dive Pressure | B34: q_D | C34: psf | D34: =J38 -> 55.060819 | G34: Landing Weight | I34: W_L | J34: ='Mission Weight'!B39*0.5 + 'Mission Weight'!E7+'Mission Weight'!E8*0.25 -> 34245.223 | K34: (25% Fuel, 50% Stores)
A35: Fuselage length/height | B35: l_L/l_H | D35: 10 | G35: Surface Area of Wing | I35: S | J35: =WingLayout!C6 -> 457
G36: CL Max Land | I36: C_LML | J36: 2.3
G37: Stall Velocity | I37: V_S | J37: =SQRT((2*J34)/(J33*J35*J36)) -> 165.56876
G38: Dynamic Dive Press. | I38: q_d | J38: =(0.5)*(J33)*(J37*1.3)^2 -> 55.060819
B47: 4.1 | H47: 4.2 | M47: STRIKE | T47: 4.2 | Y47: A2A | AH47: 4.3
M48: Clean Cruise | Y48: Clean Cruise
B49: Preliminary Weight: Strike | F49: Weight (lb)
B50: Operating Empty Weight (W_OE) | F50: =F51+F52+F53 -> 26236.179 | L50: Weight (lb) | N50: Distance (in) | Q50: Moment (lb-in) | X50: Weight (lb) | Z50: Distance (in) | AC50: Moment (lb-in) | AH50: Payload | AI50: Gear | AJ50: % Fuel | AK50: FS (in) | AL50: %MAC | AM50: W_Fuel (lbs)
C51: Empty Weight (W_E) | F51: ='Mission Weight'!E7 -> 25876.179 | H51: Item | J51: Name | L51: W | M51: X | N51: Y | O51: Z | P51: X | Q51: Y | R51: Z | T51: Item | V51: Name | X51: W | Y51: X | Z51: Y | AA51: Z | AB51: X | AC51: Y | AD51: Z | AH51: Full Payload | AI51: Up | AJ51: 1 | AK51: =((L52*M52)+(L53*M53)+(L54*M54)+(L55*M55)+(L57*M57)+(AM51*M56))/(SUM(L52+L53+L54+L55+L57+AM51)) -> 401.98384 | AL51: =100*((AK51-WingLayout!F14)/WingLayout!F11) -> 34.267549 | AM51: =F54*0.01 -> 182.76179
...

Sheet IGNORE THIS PAGE
B1: 4.1 | K1: 4.2
B2: Needs: Strike | F2: Weight (lb) | N2: Weight (lb) | O2: X (Frame Station) | P2: Y (Butt Line, b/2) | Q2: Y (Butt Line) | R2: Z (Water Line) | T2: X:W | U2: Y:W, b/2 | V2: Y:W | W2: Z:W | AA2: X (FS) Estimator | AC2: Used F-16 for now. | AL2: Y (BL, b/2) Estimator | AR2: Z (WL) Estimator
B3: Operating Empty Weight (W_OE) | F3: =F4+F5+F6 -> 26236.179 | K3: Wing | N3: =K50 -> 2464.3685 | O3: =AI6 -> 420 | P3: =AO6 -> 120 | Q3: 0 | R3: =AV6 -> 95.974032 | T3: =O3*N3 -> 1035034.8 | U3: =P3*N3 -> 295724.22 | V3: =Q3*N3 -> 0 | W3: =R3*N3 -> 236515.39 | AC3: Values sourced from CHATGPT
C4: Empty Weight (W_E) | F4: =[1]Estimator!E7 -> 25876.179 | K4: H-Tail | N4: 800 | O4: =AI15 -> 593.19684 | P4: =AO15 -> 33.255814 | Q4: 0 | R4: =AV15 -> 90.525377 | T4: =O4*N4 -> 474557.47 | U4: =P4*N4 -> 26604.651 | V4: =Q4*N4 -> 0 | W4: =R4*N4 -> 72420.302 | AC4: They physically make sense
C5: Trapped Fuel and Oil (W_tfo) | F5: 120 | K5: V-Tail | N5: 700 | O5: =AI24 -> 617.15829 | P5: =AO24 -> 28.575758 | Q5: 0 | R5: =AV24 -> 123.57576 | T5: =O5*N5 -> 432010.8 | U5: =P5*N5 -> 20003.03 | V5: =Q5*N5 -> 0 | W5: =R5*N5 -> 86503.03 | AA5: Inputs: Wing (in) | AE5: 𝜆 | AF5: MAC | AG5: y_MAC | AH5: FS_LE_MAC | AI5: X (FS) | AL5: Inputs: Wing | AO5: Y (BL) | AR5: Inputs: Wing | AV5: Z (WL)
C6: Crew Weight (W_CREW) | F6: 240 | K6: Fuselage | N6: =E50 -> 4881.7404 | O6: =AE33 -> 254.99 | Q6: 0 | T6: =O6*N6 -> 1244795 | V6: =Q6*N6 -> 0 | AA6: Wing Span (b) | AC6: =WingLayout!C7 -> 45 | AE6: =WingLayout!C8 -> 0.5 | AF6: =(2/3) * AC7 * (( 1 + AE6 + AE6^2) / (1 + AE6)) -> 10.531687 | AG6: =(AC6/6) * ((1 + 2*AE6) / (1 + AE6)) -> 10 | AH6: =AC11 + (AG6 * TAN(RADIANS(AC9)) * 12) -> 358.67643 | AI6: =AH6 + (AC10*AF6*12) -> 420 | AL6: y_MAC | AM6: =AG6 -> 10 | AO6: =(AM7*(1+2*AE6))/(3*(1+AE6))*12 -> 120 | AR6: Wing Span (b) | AT6: =AC6 -> 45 | AV6: =AT11 + (AG6*TAN(RADIANS(AT7))) * 12 + AT9 * AT8 * AF6 * 12 -> 95.974032
B7: Fuel (W_F) | F7: =[1]Estimator!E8 -> 18276.179 | K7: Engines/Nacelles | N7: 6000 | O7: =AE33 -> 254.99 | Q7: 0 | T7: =O7*N7 -> 1529940 | V7: =Q7*N7 -> 0 | AA7: Root Chord (c) | AC7: =WingLayout!F8 -> 13.540741 | AD7: 11.5 | AL7: b_semi | AM7: =AC6/2 -> 22.5 | AR7: Dihedral | AT7: 4
B8: W_OE + 60% Fuel | F8: =F3+(F7*0.6) -> 37201.886 | K8: Landing Gear, Nose | N8: =F12*0.18 -> 405.10009 | O8: 180 | Q8: 0 | T8: =O8*N8 -> 72918.017 | V8: =Q8*N8 -> 0 | AA8: Tip chord (c_t) | AC8: =WingLayout!F16 -> 6.7703704 | AD8: 4.5 | AR8: Thickness Ratio | AT8: 0.12
B9: W_OE + W_F | F9: =F3+F7 -> 44512.357 | K9: Landing Gear, Main | N9: =F12*0.82 -> 1845.456 | O9: 330 | Q9: 0 | T9: =O9*N9 -> 609000.47 | V9: =Q9*N9 -> 0 | AA9: LE Sweep (𝜆) | AC9: =WingLayout!C9 -> 20 | AD9: 40 | AR9: CG Fraction (Z-Axis) | AT9: 0.5
B10: Payload Weight (W_PL) | F10: =[1]Estimator!B14 -> 5500 | K10: Crew & Payload (A2A) | Q10: 0 | T10: =O10*N10 -> 0 | V10: =Q10*N10 -> 0 | AA10: CG Fraction (X-Axis) | AC10: =(420-WingLayout!F14)/WingLayout!F11 -> 0.48523067 | AR10: MAC | AT10: 8.51
B11: W_OE + WF + W_PL | F11: =F3+F7+F10 -> 50012.357 | AA11: Apex Station | AC11: =WingLayout!C10 -> 315 | AR11: WL Apex | AT11: 80
B12: Landing Gear | F12: =F11*0.045 -> 2250.5561 | K12: Totals | N12: =SUM(N3:N10) -> 17096.665 | O12: =T12/N12 -> 315.7491 | T12: =SUM(T3:T10) -> 5398256.5
AA14: Inputs: H-Tail (ft) | AE14: 𝜆 | AF14: MAC | AG14: y_MAC | AH14: FS_LE_MAC | AI14: X (FS) | AL14: Inputs: H-Tail | AO14: Y (BL) | AR14: Inputs: H-Tail | AV14: Z (WL)
K15: (Once all yellow cells have information inputted, the red cells will be correct) | AA15: Wing Span (b) | AC15: 13 | AE15: =AC17/AC16 -> 0.38709677 | AF15: =(2/3) * AC16 * (( 1 + AE15 + AE15^2) / (1 + AE15)) -> 5.7248062 | AG15: =(AC15/6) * ((1 + 2*AE15) / (1 + AE15)) -> 2.7713178 | AH15: =AC20 + (AG15 * TAN(RADIANS(AC18)) * 12) -> 565.71777 | AI15: =AH15 + (AC19*AF15*12) -> 593.19684 | AL15: y_MAC | AM15: =AG15 -> 2.7713178 | AO15: =(AM16*(1+2*AE15))/(3*(1+AE15))*12 -> 33.255814 | AR15: Wing Span (b) | AT15: =AC15 -> 13 | AV15: =AT20 + (AG15*TAN(RADIANS(AT16))) * 12 + AT18 * AT17 * AF15 * 12 -> 90.525377
B16: Needs: A2A | F16: Weight (lb) | K16: KEY: | AA16: Root Chord (c) | AC16: 7.75 | AL16: b_semi | AM16: =AC15/2 -> 6.5 | AR16: Dihedral | AT16: -5
B17: Operating Empty Weight (W_OE) | F17: =F18+F19+F20 -> 25167.589 | L17: Relies on red cells | AA17: Tip chord (c_t) | AC17: 3 | AR17: Thickness Ratio | AT17: 0.1
C18: Empty Weight (W_E) | F18: =[1]Estimator!B7 -> 24807.589 | L18: Missing information, using F-16C estimate instead (ChatGPT) | AA18: LE Sweep (𝜆) | AC18: 35 | AR18: CG Fraction (Z-Axis) | AT18: 0.5
C19: Trapped Fuel and Oil (W_tfo) | F19: 120 | L19: This will need to be calculated by me | AA19: CG Fraction | AC19: 0.4 | AR19: MAC | AT19: =AF15 -> 5.7248062
C20: Crew Weight (W_CREW) | F20: 240 | L20: This is the NET moment created by the wing. Table Shown below breaking this down | AA20: Apex Station | AC20: =WingLayout!B53 -> 542.4318 | AR20: WL Apex | AT20: 90
B21: Fuel (W_F) | F21: =[1]Estimator!B8 -> 19307.589
B22: W_OE + 60% Fuel | F22: =F17+(F21*0.6) -> 36752.142
B23: W_OE + W_F | F23: =F17+F21 -> 44475.177 | AA23: Inputs: V-Tail (ft) | AE23: 𝜆 | AF23: MAC | AG23: y_MAC | AH23: FS_LE_MAC | AI23: X (FS) | AL23: Inputs: V-Tail | AO23: Y (BL) | AR23: Inputs: V-Tail | AV23: Z (WL)
B24: Payload Weight (W_PL) | F24: =[1]Estimator!B39 -> 7600 | K24: Y:W Break Down | M24: Y (BL) (+/-) | N24: Moment (+) | O24: Moment(-) | P24: Sum of Moments | AA24: Wing Span (b) | AC24: 11.5 | AE24: =AC26/AC25 -> 0.32 | AF24: =(2/3) * AC25 * (( 1 + AE24 + AE24^2) / (1 + AE24)) -> 8.979798 | AG24: =(AC24/6) * ((1 + 2*AE24) / (1 + AE24)) -> 2.3813131 | AH24: =AC29 + (AG24 * TAN(RADIANS(AC27)) * 12) -> 574.05526 | AI24: =AH24 + (AC28*AF24*12) -> 617.15829 | AL24: y_MAC | AM24: =AG24 -> 2.3813131 | AO24: =(AM25*(1+2*AE24))/(3*(1+AE24))*12 -> 28.575758 | AR24: Root LE Height | AT24: 95 | AV24: =AT24+(AT29*12) -> 123.57576
B25: W_OE + WF + W_PL | F25: =F17+F21+F24 -> 52075.177 | K25: Wing | M25: =O1 -> 0 | N25: =(M25/2)*M1 -> 0 | O25: =(M25/2)*M1*(-1) -> 0 | P25: =N25+O25 -> 0 | AA25: Root Chord (c) | AC25: 12.5 | AL25: b_semi | AM25: =AC24/2 -> 5.75 | AR25: Fin Height (b_VT) | AT25: 11.5
K26: H-Tail | M26: =O2 -> X (Frame Station) | N26: =(M26/2)*M2 -> #VALUE! | O26: =(M26/2)*M2*(-1) -> #VALUE! | P26: =N26+O26 -> #VALUE! | AA26: Tip chord (c_t) | AC26: 4 | AR26: Root Chord (c_VT) | AT26: 12.5
K27: V-Tail | M27: =O3 -> 420 | N27: =(M27/2)*M3 -> 0 | O27: =(M27/2)*M3*(-1) -> 0 | P27: =N27+O27 -> 0 | AA27: LE Sweep (𝜆) | AC27: 50 | AR27: Tip Chord (c_TVT | AT27: 4
K28: Essentially disregard the Y (BL) calcs, they all end up 0 in the end, I just added the CG location on a single side | AA28: CG Fraction | AC28: 0.4 | AR28: 𝜆_VT | AT28: =AT27/AT26 -> 0.32
AA29: Apex Station | AC29: 540 | AR29: z_MAC_VT | AT29: =(AT25/6) * ((1+2*AT28)/(1+AT28)) -> 2.3813131
AA32: Inputs: Fuselage | AE32: X (FS)
B33: 4.3 | AA33: K | AB33: 0.43 | AE33: =AB34*AB33 -> 254.99
D34: Clean Config | J34: Full Config | P34: Worst Case Config | AA34: Length | AB34: 593
AA35: x_nose | AB35: 0
B36: Payload | C36: Gear | D36: % Fuel | E36: FS (in) | F36: %MAC | H36: Payload | I36: Gear | J36: % Fuel | K36: FS (in) | L36: %MAC | N36: Payload | O36: Gear | P36: % Fuel | Q36: FS (in) | R36: %MAC
B37: Full Payload | C37: Up | D37: 1 | H37: Full Payload | I37: Up | J37: 1 | N37: Full Payload | O37: Up | P37: 1
D38: 60 | J38: 60 | P38: 60 | AA38: Inputs: Engine
D39: 100 | J39: 100 | P39: 100 | AA39: K | AB39: 0.5
B40: No Payload | C40: Down | D40: 1 | H40: No Payload | I40: Down | J40: 1 | N40: No Payload | O40: Down | P40: 1
D41: 60 | J41: 60 | P41: 60
D42: 100 | J42: 100 | P42: 100
AO46: Numbers are multiplied by 12 to get the answer in inches along each chord
...

Sheet Mission Weight
A1: Next-Gen Navy Fighter — Preliminary Takeoff Weight Estimator (Method 2.1)
A2: Units: c_t in 1/hr, V in kt, R in nm, E in hr. Segment Type must be: range, endurance, or discrete.
A3: Edit the yellow cells only. Outputs compute automatically. ε and δ are decimals (e.g., 0.50, 0.06).
A5: Summary (read-only)
A6: A2A: W₀ (lb) | B6: =B32 -> 49615.177 | D6: Strike: W₀ (lb) | E6: =B58 -> 51752.357
A7: A2A: Wₑ (lb) | B7: =B33 -> 24807.589 | D7: Strike: Wₑ (lb) | E7: =B59 -> 25876.179
A8: A2A: W_f (lb) | B8: =B34 -> 19307.589 | D8: Strike: W_f (lb) | E8: =B60 -> 18276.179
A12: A2A Mission (700 nm out & back, 2-min AB, 30-min reserve)
A13: Inputs (A2A)
A14: Payload W_PL (lb) | B14: 5500
A15: Empty-weight fraction ε (decimal) | B15: 0.5
A16: Fuel allowance δ (decimal) | B16: 0.06
A18: Segment | B18: Type | C18: c_t (1/hr) | D18: L/D | E18: V (kt) | F18: R (nm) | G18: E (hr) | H18: k | I18: Exponent | J18: Factor W(i+1)/W(i)
A19: Warm-up/Taxi | B19: discrete | H19: 0.99 | I19: =IF(B19="range",(C19/D19)*(F19/E19),IF(B19="endurance",(C19/D19)*G19,0)) -> 0 | J19: =IF(OR(B19="range",B19="endurance"),EXP(-I19),H19) -> 0.99
A20: Takeoff | B20: discrete | H20: 0.995 | I20: =IF(B20="range",(C20/D20)*(F20/E20),IF(B20="endurance",(C20/D20)*G20,0)) -> 0 | J20: =IF(OR(B20="range",B20="endurance"),EXP(-I20),H20) -> 0.995
A21: Climb | B21: discrete | H21: 0.98 | I21: =IF(B21="range",(C21/D21)*(F21/E21),IF(B21="endurance",(C21/D21)*G21,0)) -> 0 | J21: =IF(OR(B21="range",B21="endurance"),EXP(-I21),H21) -> 0.98
A22: Outbound Cruise | B22: range | C22: 0.8 | D22: 11 | E22: 500 | F22: 1000 | I22: =IF(B22="range",(C22/D22)*(F22/E22),IF(B22="endurance",(C22/D22)*G22,0)) -> 0.14545455 | J22: =IF(OR(B22="range",B22="endurance"),EXP(-I22),H22) -> 0.86462919
A23: Combat (AB 2 min) | B23: endurance | C23: 2.2 | D23: 5 | G23: 0.083333333 | I23: =IF(B23="range",(C23/D23)*(F23/E23),IF(B23="endurance",(C23/D23)*G23,0)) -> 0.036666667 | J23: =IF(OR(B23="range",B23="endurance"),EXP(-I23),H23) -> 0.96399741
A24: Return Cruise | B24: range | C24: 0.8 | D24: 11 | E24: 500 | F24: 1000 | I24: =IF(B24="range",(C24/D24)*(F24/E24),IF(B24="endurance",(C24/D24)*G24,0)) -> 0.14545455 | J24: =IF(OR(B24="range",B24="endurance"),EXP(-I24),H24) -> 0.86462919
A25: Descent | B25: discrete | H25: 1 | I25: =IF(B25="range",(C25/D25)*(F25/E25),IF(B25="endurance",(C25/D25)*G25,0)) -> 0 | J25: =IF(OR(B25="range",B25="endurance"),EXP(-I25),H25) -> 1
A26: Reserve Loiter (30 min) | B26: endurance | C26: 0.8 | D26: 11 | G26: 0.5 | I26: =IF(B26="range",(C26/D26)*(F26/E26),IF(B26="endurance",(C26/D26)*G26,0)) -> 0.036363636 | J26: =IF(OR(B26="range",B26="endurance"),EXP(-I26),H26) -> 0.96428958
A28: Outputs (A2A)
A29: Π (product of factors) | B29: =PRODUCT(J19:J26) -> 0.67085318
A30: Raw fuel fraction (1−Π) | B30: =1-B29 -> 0.32914682
A31: Final φ (add δ) | B31: =B30+B16 -> 0.38914682
A32: W₀ (lb) | B32: =B14/(1-B15-B31) -> 49615.177
A33: Wₑ = ε·W₀ (lb) | B33: =B15*B32 -> 24807.589
A34: W_f = φ·W₀ (lb) | B34: =B31*B32 -> 19307.589
A37: Strike Mission (650 nm out/back, 50 nm SL ingress & egress, 30-min reserve)
A38: Inputs (Strike)
A39: Payload W_PL (lb) | B39: 7600
A40: Empty-weight fraction ε (decimal) | B40: 0.5
A41: Fuel allowance δ (decimal) | B41: 0.06
A43: Segment | B43: Type | C43: c_t (1/hr) | D43: L/D | E43: V (kt) | F43: R (nm) | G43: E (hr) | H43: k | I43: Exponent | J43: Factor W(i+1)/W(i)
A44: Warm-up/Taxi | B44: discrete | H44: 0.99 | I44: =IF(B44="range",(C44/D44)*(F44/E44),IF(B44="endurance",(C44/D44)*G44,0)) -> 0 | J44: =IF(OR(B44="range",B44="endurance"),EXP(-I44),H44) -> 0.99
A45: Takeoff | B45: discrete | H45: 0.995 | I45: =IF(B45="range",(C45/D45)*(F45/E45),IF(B45="endurance",(C45/D45)*G45,0)) -> 0 | J45: =IF(OR(B45="range",B45="endurance"),EXP(-I45),H45) -> 0.995
A46: Climb | B46: discrete | H46: 0.98 | I46: =IF(B46="range",(C46/D46)*(F46/E46),IF(B46="endurance",(C46/D46)*G46,0)) -> 0 | J46: =IF(OR(B46="range",B46="endurance"),EXP(-I46),H46) -> 0.98
A47: Outbound Cruise | B47: range | C47: 0.8 | D47: 9 | E47: 500 | F47: 650 | I47: =IF(B47="range",(C47/D47)*(F47/E47),IF(B47="endurance",(C47/D47)*G47,0)) -> 0.11555556 | J47: =IF(OR(B47="range",B47="endurance"),EXP(-I47),H47) -> 0.89087108
A48: Ingress Dash (SL MIL 50 nm) | B48: range | C48: 1.3 | D48: 6 | E48: 600 | F48: 50 | I48: =IF(B48="range",(C48/D48)*(F48/E48),IF(B48="endurance",(C48/D48)*G48,0)) -> 0.018055556 | J48: =IF(OR(B48="range",B48="endurance"),EXP(-I48),H48) -> 0.98210647
A49: Egress Dash (SL MIL 50 nm) | B49: range | C49: 1.3 | D49: 6 | E49: 600 | F49: 50 | I49: =IF(B49="range",(C49/D49)*(F49/E49),IF(B49="endurance",(C49/D49)*G49,0)) -> 0.018055556 | J49: =IF(OR(B49="range",B49="endurance"),EXP(-I49),H49) -> 0.98210647
...

Sheet 3.1.2

Sheet WingLayout
A1: Overall Aircraft Configuration – Wing Layout Tool
A3: Global Inputs (orange cells are editable)
A4: WING | C4: DRIVING NUMBERS
A5: Parameter | B5: Units | C5: Value | P5: 167.24 | R5: 374
A6: Wing Area S | B6: ft^2 | C6: 457 | D6: 377.81 | E6: Aspect Ratio AR | F6: =(C7)^2/(C6) -> 4.4310722
A7: Wing Span b | B7: ft | C7: 45 | D7: 40 | E7: Semi-span (in) | F7: =(C7)*12/2 -> 270 | H7: ='Structural Weight-MatProperties'!K233 -> 12.268293
A8: Taper Ratio λ | B8: - | C8: 0.5 | D8: 0.33 | E8: Root chord c_r (ft) | F8: =2*C6/(C7*(1+C8)) -> 13.540741
A9: LE Sweep Λ_LE | B9: deg | C9: 20 | E9: Root chord c_r (in) | F9: =12*F8 -> 162.48889
A10: Root LE X intercept (XLE_root) | B10: in | C10: 315 | E10: Tip chord c_t (in) | F10: =C8*F9 -> 81.244444
E11: MAC (in) | F11: =12*(2/3*F8*((1+C8+C8^2)/(1+C8))) -> 126.38025
E12: y_bar (in) | F12: =12*((C7)/6*((1+2*C8)/(1+C8))) -> 120
E13: m_LE = tan(Λ_LE) | F13: =TAN(RADIANS(C9)) -> 0.36397023
E14: LEMAC X (in) = XLE(y_bar) | F14: =C10+F13*F12 -> 358.67643
E15: TEMAC X (in) | F15: =F14+F11 -> 485.05668
E16: Tip chord c_t (ft) | F16: =F10/12 -> 6.7703704
A17: Spanwise Geometry (from centerline to tip)
A18: Station | B18: y (in) | C18: Chord c(y) (in) | D18: XLE(y) (in) | E18: Xc/4 (in) | F18: Xc/2 (in) | G18: XTE(y) (in)
A19: 0% b/2 | B19: =F7*0 -> 0 | C19: =F9 - (F9-F10)*(B19/F7) -> 162.48889 | D19: =C10+F13*B19 -> 315 | E19: =D19+0.25*C19 -> 355.62222 | F19: =D19+0.5*C19 -> 396.24444 | G19: =D19+C19 -> 477.48889
A20: 25% b/2 | B20: =F7*0.25 -> 67.5 | C20: =F9 - (F9-F10)*(B20/F7) -> 142.17778 | D20: =C10+F13*B20 -> 339.56799 | E20: =D20+0.25*C20 -> 375.11244 | F20: =D20+0.5*C20 -> 410.65688 | G20: =D20+C20 -> 481.74577
A21: 50% b/2 | B21: =F7*0.5 -> 135 | C21: =F9 - (F9-F10)*(B21/F7) -> 121.86667 | D21: =C10+F13*B21 -> 364.13598 | E21: =D21+0.25*C21 -> 394.60265 | F21: =D21+0.5*C21 -> 425.06931 | G21: =D21+C21 -> 486.00265
A22: 75% b/2 | B22: =F7*0.75 -> 202.5 | C22: =F9 - (F9-F10)*(B22/F7) -> 101.55556 | D22: =C10+F13*B22 -> 388.70397 | E22: =D22+0.25*C22 -> 414.09286 | F22: =D22+0.5*C22 -> 439.48175 | G22: =D22+C22 -> 490.25953
A23: 100% b/2 | B23: =F7*1 -> 270 | C23: =F9 - (F9-F10)*(B23/F7) -> 81.244444 | D23: =C10+F13*B23 -> 413.27196 | E23: =D23+0.25*C23 -> 433.58307 | F23: =D23+0.5*C23 -> 453.89419 | G23: =D23+C23 -> 494.51641
A26: Horizontal stabilizer
A27: Global Inputs (yellow cells editable) — dimensions measured from Tail Station 0 (TS0)
A29: Parameter | B29: Units | C29: Value | E29: Derived Geometry (H-Stab)
A30: Stab Area S_H | B30: ft^2 | C30: 110 | D30: 75.81 | E30: Aspect Ratio AR_H | F30: =(C31)^2/(C30) -> 3.2818182
A31: Stab Span b_H | B31: ft | C31: 19 | D31: 17.5 | E31: Semi-span (in) | F31: =(C31)*12/2 -> 114
A32: Taper Ratio λ_H | B32: - | C32: 0.5 | E32: Root chord c_r,H (ft) | F32: =2*C30/(C31*(1+C32)) -> 7.7192982
A33: LE Sweep Λ_LE,H | B33: deg | C33: 29 | E33: Root chord c_r,H (in) | F33: =12*F32 -> 92.631579
A34: Root LE X intercept (XLE_root,H) | B34: in | C34: 18.703 | E34: Tip chord c_t,H (in) | F34: =C32*F33 -> 46.315789
A35: Tail Arm l_H (wing 1/4c to H-stab 1/4c) | B35: in | C35: 216.96 | D35: 216.96 | E35: MAC_H (in) | F35: =12*(2/3*F32*((1+C32+C32^2)/(1+C32))) -> 72.046784
A36: Wing Area S (for V_H check) | B36: ft^2 | C36: =C6 -> 457 | E36: ȳ_c,H (in) | F36: =12*((C31)/6*((1+2*C32)/(1+C32))) -> 50.666667
A37: Wing MAC (for V_H check) | B37: in | C37: =F11 -> 126.38025 | E37: m_LE,H = tan(Λ_LE,H) | F37: =TAN(RADIANS(C33)) -> 0.55430905
E38: LEMAC_H X (in) = XLE_H(ȳ_c,H) | F38: =C34+F37*F36 -> 46.787992
E39: TEMAC_H X (in) | F39: =F38+F35 -> 118.83478
E40: Vh (Hor Tail Volume) | F40: =(C30*(C35))/(C6*(F11)) -> 0.41321584 | J40: HORI GRAPH
A41: Spanwise Geometry (Centerline → Tip, H-Stab) | J41: XLE_REL | K41: XTE_REL
A42: Station | B42: y (in) | C42: Chord c_H(y) (in) | D42: XLE_H(y) (in) | E42: Xc/4_H (in) | F42: Xc/2_H (in) | G42: XTE_H(y) (in) | J42: =B53+ D43 -> 561.1348 | K42: =B53 + G43 -> 653.76638
A43: 0% b_H/2 | B43: =F31*0 -> 0 | C43: =F33 - (F33-F34)*(B43/F31) -> 92.631579 | D43: =C34+F37*B43 -> 18.703 | E43: =D43+0.25*C43 -> 41.860895 | F43: =D43+0.5*C43 -> 65.018789 | G43: =D43+C43 -> 111.33458 | J43: =B53+ D44 -> 576.93261 | K43: =B53 + G44 -> 657.98524
A44: 25% b_H/2 | B44: =F31*0.25 -> 28.5 | C44: =F33 - (F33-F34)*(B44/F31) -> 81.052632 | D44: =C34+F37*B44 -> 34.500808 | E44: =D44+0.25*C44 -> 54.763966 | F44: =D44+0.5*C44 -> 75.027124 | G44: =D44+C44 -> 115.55344 | J44: =B53+ D45 -> 592.73042 | K44: =B53 + G45 -> 662.2041
...

Sheet Maneuver
C2: Variable | D2: Value | E2: Units
C3: rho | D3: 0.002378 | E3: slug/ft^3
C4: v | D4: 300 | E4: ft/s
C5: S | D5: 600 | E5: ft^2
C6: CL,max | D6: 0.9
C7: T | D7: 35400 | E7: lbf
C10: vstall

Sheet Takeoff Calculator
A1: W | B1: 5072 | C1: lbf | E1: runway | F1: 300 | G1: ft | J1: dx(ft) | K1: x(ft) | L1: F_net(x) | M1: V^2 | N1: V (ft/s) | O1: q | P1: L | Q1: D | R1: F_Fric (x) | S1: V (kn) | U1: y(ft) | V1: y dot (ft/s) | W1: y ddot (ft/s^2)
A2: density | B2: 0.002378 | C2: slug/ft^3 | E2: vstall | F2: =SQRT((2*B1)/(B2*B16*B14)) -> 62.847328 | G2: ft/s | K2: 0 | L2: =$B$10+$B$11-Q2-R2 -> 1392.9332 | M2: 0 | N2: 0 | O2: 0 | P2: 0 | Q2: 0 | R2: =$B$7*($B$1-O2) -> 101.44 | S2: 0 | U2: 0 | V2: 0 | W2: =(P2-$B$1)/$B$20 -> -32.174
A3: b | B3: 41.5 | C3: ft | E3: v_to | F3: =1.2*F2 -> 75.416793 | G3: ft/s | J3: 5 | K3: 5 | L3: =$B$10+$B$11-Q3-R3 -> 1375.5356 | M3: =M2+2*(L2/$B$20)*J3 -> 88.360079 | N3: =SQRT(M3) -> 9.4000042 | O3: =0.5*$B$2*M3 -> 0.10506013 | P3: =O3*$B$16*$B$19 -> 78.7951 | Q3: =O3*$B$16*$B$21 -> 17.399701 | R3: =$B$7*($B$1-O3) -> 101.4379 | S3: =0.592*N3 -> 5.5648025 | U3: =V3*(J3/N3) -> -9.1030928 | V3: =W2*(J3/N3) -> -17.113822 | W3: =(P3-$B$1)/$B$20 -> -31.674167
A4: AR | B4: 2.8704167 | E4: a_to | F4: =F3^2/(2*F1) -> 9.4794879 | G4: ft/s^2 | J4: 5 | K4: 10 | L4: =$B$10+$B$11-Q4-R4 -> 1358.3553 | M4: =M3+2*(L3/$B$20)*J4 -> 175.61655 | N4: =SQRT(M4) -> 13.252039 | O4: =0.5*$B$2*M4 -> 0.20880808 | P4: =O4*$B$16*$B$19 -> 156.60606 | Q4: =O4*$B$16*$B$21 -> 34.582081 | R4: =$B$7*($B$1-O4) -> 101.43582 | S4: =0.592*N4 -> 7.8452073 | U4: =V4*(J4/N4) -> -4.5089952 | V4: =W3*(J4/N4) -> -11.950676 | W4: =(P4-$B$1)/$B$20 -> -31.180577
A5: e | B5: 0.75 | E5: a_cat | F5: =F4-B10/B20 -> -215.07879 | G5: ft/s^2 | J5: 5 | K5: 15 | L5: =$B$10+$B$11-Q5-R5 -> 1341.3895 | M5: =M4+2*(L4/$B$20)*J5 -> 261.78319 | N5: =SQRT(M5) -> 16.179716 | O5: =0.5*$B$2*M5 -> 0.31126022 | P5: =O5*$B$16*$B$19 -> 233.44516 | Q5: =O5*$B$16*$B$21 -> 51.549855 | R5: =$B$7*($B$1-O5) -> 101.43377 | S5: =0.592*N5 -> 9.5783916 | U5: =V5*(J5/N5) -> -2.9777099 | V5: =W4*(J5/N5) -> -9.6356999 | W5: =(P5-$B$1)/$B$20 -> -30.693151
A6: C_DO | B6: 0.045 | J6: 5 | K6: 20 | L6: =$B$10+$B$11-Q6-R6 -> 1324.6357 | M6: =M5+2*(L5/$B$20)*J6 -> 346.87363 | N6: =SQRT(M6) -> 18.624544 | O6: =0.5*$B$2*M6 -> 0.41243274 | P6: =O6*$B$16*$B$19 -> 309.32456 | Q6: =O6*$B$16*$B$21 -> 68.305703 | R6: =$B$7*($B$1-O6) -> 101.43175 | S6: =0.592*N6 -> 11.02573 | U6: =V6*(J6/N6) -> -2.2121278 | V6: =W5*(J6/N6) -> -8.239974 | W6: =(P6-$B$1)/$B$20 -> -30.211814
A7: mu | B7: 0.02 | J7: 5 | K7: 25 | L7: =$B$10+$B$11-Q7-R7 -> 1308.0912 | M7: =M6+2*(L6/$B$20)*J7 -> 430.90129 | N7: =SQRT(M7) -> 20.758162 | O7: =0.5*$B$2*M7 -> 0.51234163 | P7: =O7*$B$16*$B$19 -> 384.25622 | Q7: =O7*$B$16*$B$21 -> 84.852272 | R7: =$B$7*($B$1-O7) -> 101.42975 | S7: =0.592*N7 -> 12.288832 | U7: =V7*(J7/N7) -> -1.7528268 | V7: =W6*(J7/N7) -> -7.2770927 | W7: =(P7-$B$1)/$B$20 -> -29.736488
A8: alpha | B8: 10 | C8: degrees | E8: V at 90% C_Lmax | F8: =SQRT((2*B1)/(B2*B16*0.9*B14)) -> 66.2469 | G8: ft/s | J8: 5 | K8: 30 | L8: =$B$10+$B$11-Q8-R8 -> 1291.7532 | M8: =M7+2*(L7/$B$20)*J8 -> 513.87945 | N8: =SQRT(M8) -> 22.668909 | O8: =0.5*$B$2*M8 -> 0.61100267 | P8: =O8*$B$16*$B$19 -> 458.252 | Q8: =O8*$B$16*$B$21 -> 101.19218 | R8: =$B$7*($B$1-O8) -> 101.42778 | S8: =0.592*N8 -> 13.419994 | U8: =V8*(J8/N8) -> -1.4466665 | V8: =W7*(J8/N8) -> -6.5588705 | W8: =(P8-$B$1)/$B$20 -> -29.267099
A9: lift curve slope | B9: 3.5577 | C9: rad^-1 | J9: 5 | K9: 35 | L9: =$B$10+$B$11-Q9-R9 -> 1275.6194 | M9: =M8+2*(L8/$B$20)*J9 -> 595.82123 | N9: =SQRT(M9) -> 24.40945 | O9: =0.5*$B$2*M9 -> 0.70843144 | P9: =O9*$B$16*$B$19 -> 531.32358 | Q9: =O9*$B$16*$B$21 -> 117.328 | R9: =$B$7*($B$1-O9) -> 101.42583 | S9: =0.592*N9 -> 14.450394 | U9: =V9*(J9/N9) -> -1.2280151 | V9: =W8*(J9/N9) -> -5.9950347 | W9: =(P9-$B$1)/$B$20 -> -28.803573
A10: T_engine | B10: 35400 | C10: lbf | J10: 5 | K10: 40 | L10: =$B$10+$B$11-Q10-R10 -> 1259.687 | M10: =M9+2*(L9/$B$20)*J10 -> 676.73956 | N10: =SQRT(M10) -> 26.014218 | O10: =0.5*$B$2*M10 -> 0.80464333 | P10: =O10*$B$16*$B$19 -> 603.4825 | Q10: =O10*$B$16*$B$21 -> 133.26228 | R10: =$B$7*($B$1-O10) -> 101.42391 | S10: =0.592*N10 -> 15.400417 | U10: =V10*(J10/N10) -> -1.0640568 | V10: =W9*(J10/N10) -> -5.5361212 | W10: =(P10-$B$1)/$B$20 -> -28.345836
A11: F_cat | B11: =F5*B20 -> -33905.627 | C11: lbf | J11: 5 | K11: 45 | L11: =$B$10+$B$11-Q11-R11 -> 1243.9536 | M11: =M10+2*(L10/$B$20)*J11 -> 756.64723 | N11: =SQRT(M11) -> 27.507221 | O11: =0.5*$B$2*M11 -> 0.89965355 | P11: =O11*$B$16*$B$19 -> 674.74016 | Q11: =O11*$B$16*$B$21 -> 148.99755 | R11: =$B$7*($B$1-O11) -> 101.42201 | S11: =0.592*N11 -> 16.284275 | U11: =V11*(J11/N11) -> -0.93656051 | V11: =W10*(J11/N11) -> -5.1524354 | W11: =(P11-$B$1)/$B$20 -> -27.893817
A12: dx | B12: 5 | C12: ft | J12: 5 | K12: 50 | L12: =$B$10+$B$11-Q12-R12 -> 1228.4168 | M12: =M11+2*(L11/$B$20)*J12 -> 835.55685 | N12: =SQRT(M12) -> 28.906 | O12: =0.5*$B$2*M12 -> 0.9934771 | P12: =O12*$B$16*$B$19 -> 745.10782 | Q12: =O12*$B$16*$B$21 -> 164.53629 | R12: =$B$7*($B$1-O12) -> 101.42013 | S12: =0.592*N12 -> 17.112352 | U12: =V12*(J12/N12) -> -0.83458763 | V12: =W11*(J12/N12) -> -4.8249181 | W12: =(P12-$B$1)/$B$20 -> -27.447443
A13: gravity | B13: 32.174 | C13: ft/s^2 | J13: 5 | K13: 55 | L13: =$B$10+$B$11-Q13-R13 -> 1213.074 | M13: =M12+2*(L12/$B$20)*J13 -> 913.48091 | N13: =SQRT(M13) -> 30.223847 | O13: =0.5*$B$2*M13 -> 1.0861288 | P13: =O13*$B$16*$B$19 -> 814.5966 | Q13: =O13*$B$16*$B$21 -> 179.88094 | R13: =$B$7*($B$1-O13) -> 101.41828 | S13: =0.592*N13 -> 17.892517 | U13: =V13*(J13/N13) -> -0.75117724 | V13: =W12*(J13/N13) -> -4.5406931 | W13: =(P13-$B$1)/$B$20 -> -27.006644
A14: C_Lmax | B14: 1.8 | J14: 5 | K14: 60 | L14: =$B$10+$B$11-Q14-R14 -> 1197.9228 | M14: =M13+2*(L13/$B$20)*J14 -> 990.4317 | N14: =SQRT(M14) -> 31.471125 | O14: =0.5*$B$2*M14 -> 1.1776233 | P14: =O14*$B$16*$B$19 -> 883.21747 | Q14: =O14*$B$16*$B$21 -> 195.03395 | R14: =$B$7*($B$1-O14) -> 101.41645 | S14: =0.592*N14 -> 18.630906 | U14: =V14*(J14/N14) -> -0.68168869 | V14: =W13*(J14/N14) -> -4.290702 | W14: =(P14-$B$1)/$B$20 -> -26.57135
J15: 5 | K15: 65 | L15: =$B$10+$B$11-Q15-R15 -> 1182.9608 | M15: =M14+2*(L14/$B$20)*J15 -> 1066.4214 | N15: =SQRT(M15) -> 32.656108 | O15: =0.5*$B$2*M15 -> 1.267975 | P15: =O15*$B$16*$B$19 -> 950.98127 | Q15: =O15*$B$16*$B$21 -> 209.99769 | R15: =$B$7*($B$1-O15) -> 101.41464 | S15: =0.592*N15 -> 19.332416 | U15: =V15*(J15/N15) -> -0.62290926 | V15: =W14*(J15/N15) -> -4.0683584 | W15: =(P15-$B$1)/$B$20 -> -26.141494
A16: S | B16: =B3^2/B4 -> 600 | C16: ft^2 | J16: 5 | K16: 70 | L16: =$B$10+$B$11-Q16-R16 -> 1168.1858 | M16: =M15+2*(L15/$B$20)*J16 -> 1141.462 | N16: =SQRT(M16) -> 33.785529 | O16: =0.5*$B$2*M16 -> 1.3571983 | P16: =O16*$B$16*$B$19 -> 1017.8987 | Q16: =O16*$B$16*$B$21 -> 224.77454 | R16: =$B$7*($B$1-O16) -> 101.41286 | S16: =0.592*N16 -> 20.001033 | U16: =V16*(J16/N16) -> -0.57254413 | V16: =W15*(J16/N16) -> -3.8687412 | W16: =(P16-$B$1)/$B$20 -> -25.717006
A17: k | B17: =1/(PI()*B4*B5) -> 0.14785769 | J17: 5 | K17: 75 | L17: =$B$10+$B$11-Q17-R17 -> 1153.5953 | M17: =M16+2*(L16/$B$20)*J17 -> 1215.5653 | N17: =SQRT(M17) -> 34.864958 | O17: =0.5*$B$2*M17 -> 1.4453071 | P17: =O17*$B$16*$B$19 -> 1083.9804 | Q17: =O17*$B$16*$B$21 -> 239.36683 | R17: =$B$7*($B$1-O17) -> 101.41109 | S17: =0.592*N17 -> 20.640055 | U17: =V17*(J17/N17) -> -0.52891042 | V17: =W16*(J17/N17) -> -3.6880879 | W17: =(P17-$B$1)/$B$20 -> -25.29782
A18: Alpha Radian | B18: =B8*(PI()/180) -> 0.17453293 | J18: 5 | K18: 80 | L18: =$B$10+$B$11-Q18-R18 -> 1139.187 | M18: =M17+2*(L17/$B$20)*J18 -> 1288.7431 | N18: =SQRT(M18) -> 35.899068 | O18: =0.5*$B$2*M18 -> 1.5323155 | P18: =O18*$B$16*$B$19 -> 1149.2366 | Q18: =O18*$B$16*$B$21 -> 253.77687 | R18: =$B$7*($B$1-O18) -> 101.40935 | S18: =0.592*N18 -> 21.252248 | U18: =V18*(J18/N18) -> -0.49074599 | V18: =W17*(J18/N18) -> -3.5234648 | W18: =(P18-$B$1)/$B$20 -> -24.88387
A19: C_L | B19: 1.25 | J19: 5 | K19: 85 | L19: =$B$10+$B$11-Q19-R19 -> 1124.9586 | M19: =M18+2*(L18/$B$20)*J19 -> 1361.0069 | N19: =SQRT(M19) -> 36.891827 | O19: =0.5*$B$2*M19 -> 1.6182372 | P19: =O19*$B$16*$B$19 -> 1213.6779 | Q19: =O19*$B$16*$B$21 -> 268.00692 | R19: =$B$7*($B$1-O19) -> 101.40764 | S19: =0.592*N19 -> 21.839961 | U19: =V19*(J19/N19) -> -0.45708567 | V19: =W18*(J19/N19) -> -3.3725451 | W19: =(P19-$B$1)/$B$20 -> -24.47509
A20: M | B20: =B1/32.174 -> 157.64282 | C20: slug | J20: 5 | K20: 90 | L20: =$B$10+$B$11-Q20-R20 -> 1110.908 | M20: =M19+2*(L19/$B$20)*J20 -> 1432.3681 | N20: =SQRT(M20) -> 37.84664 | O20: =0.5*$B$2*M20 -> 1.7030857 | P20: =O20*$B$16*$B$19 -> 1277.3143 | Q20: =O20*$B$16*$B$21 -> 282.05924 | R20: =$B$7*($B$1-O20) -> 101.40594 | S20: =0.592*N20 -> 22.405211 | U20: =V20*(J20/N20) -> -0.42717877 | V20: =W19*(J20/N20) -> -3.2334561 | W20: =(P20-$B$1)/$B$20 -> -24.071415
A21: C_D | B21: =B6+B17*B19^2 -> 0.27602764 | J21: 5 | K21: 95 | L21: =$B$10+$B$11-Q21-R21 -> 1097.0329 | M21: =M20+2*(L20/$B$20)*J21 -> 1502.8381 | N21: =SQRT(M21) -> 38.766455 | O21: =0.5*$B$2*M21 -> 1.7868745 | P21: =O21*$B$16*$B$19 -> 1340.1558 | Q21: =O21*$B$16*$B$21 -> 295.93605 | R21: =$B$7*($B$1-O21) -> 101.40426 | S21: =0.592*N21 -> 22.949742 | U21: =V21*(J21/N21) -> -0.40043262 | V21: =W20*(J21/N21) -> -3.1046707 | W21: =(P21-$B$1)/$B$20 -> -23.672783
J22: 5 | K22: 100 | L22: =$B$10+$B$11-Q22-R22 -> 1083.331 | M22: =M21+2*(L21/$B$20)*J22 -> 1572.4278 | N22: =SQRT(M22) -> 39.65385 | O22: =0.5*$B$2*M22 -> 1.8696167 | P22: =O22*$B$16*$B$19 -> 1402.2125 | Q22: =O22*$B$16*$B$21 -> 309.63953 | R22: =$B$7*($B$1-O22) -> 101.40261 | S22: =0.592*N22 -> 23.475079 | U22: =V22*(J22/N22) -> -0.37637312 | V22: =W21*(J22/N22) -> -2.9849286 | W22: =(P22-$B$1)/$B$20 -> -23.279129
J23: 5 | K23: 105 | L23: =$B$10+$B$11-Q23-R23 -> 1069.8003 | M23: =M22+2*(L22/$B$20)*J23 -> 1641.1484 | N23: =SQRT(M23) -> 40.51109 | O23: =0.5*$B$2*M23 -> 1.9513255 | P23: =O23*$B$16*$B$19 -> 1463.4941 | Q23: =O23*$B$16*$B$21 -> 323.17187 | R23: =$B$7*($B$1-O23) -> 101.40097 | S23: =0.592*N23 -> 23.982566 | U23: =V23*(J23/N23) -> -0.35461644 | V23: =W22*(J23/N23) -> -2.8731798 | W23: =(P23-$B$1)/$B$20 -> -22.890392
J24: 5 | K24: 110 | L24: =$B$10+$B$11-Q24-R24 -> 1056.4386 | M24: =M23+2*(L23/$B$20)*J24 -> 1709.0107 | N24: =SQRT(M24) -> 41.340183 | O24: =0.5*$B$2*M24 -> 2.0320138 | P24: =O24*$B$16*$B$19 -> 1524.0103 | Q24: =O24*$B$16*$B$21 -> 336.53518 | R24: =$B$7*($B$1-O24) -> 101.39936 | S24: =0.592*N24 -> 24.473388 | U24: =V24*(J24/N24) -> -0.33484857 | V24: =W23*(J24/N24) -> -2.7685402 | W24: =(P24-$B$1)/$B$20 -> -22.50651
J25: 5 | K25: 115 | L25: =$B$10+$B$11-Q25-R25 -> 1043.2438 | M25: =M24+2*(L24/$B$20)*J25 -> 1776.0254 | N25: =SQRT(M25) -> 42.142917 | O25: =0.5*$B$2*M25 -> 2.1116943 | P25: =O25*$B$16*$B$19 -> 1583.7707 | Q25: =O25*$B$16*$B$21 -> 349.73159 | R25: =$B$7*($B$1-O25) -> 101.39777 | S25: =0.592*N25 -> 24.948607 | U25: =V25*(J25/N25) -> -0.31681007 | V25: =W24*(J25/N25) -> -2.6702601 | W25: =(P25-$B$1)/$B$20 -> -22.127423
J26: 5 | K26: 120 | L26: =$B$10+$B$11-Q26-R26 -> 1030.2138 | M26: =M25+2*(L25/$B$20)*J26 -> 1842.2031 | N26: =SQRT(M26) -> 42.920894 | O26: =0.5*$B$2*M26 -> 2.1903795 | P26: =O26*$B$16*$B$19 -> 1642.7847 | Q26: =O26*$B$16*$B$21 -> 362.76318 | R26: =$B$7*($B$1-O26) -> 101.39619 | S26: =0.592*N26 -> 25.409169 | U26: =V26*(J26/N26) -> -0.30028479 | V26: =W25*(J26/N26) -> -2.5776983 | W26: =(P26-$B$1)/$B$20 -> -21.753071
J27: 5 | K27: 125 | L27: =$B$10+$B$11-Q27-R27 -> 1017.3465 | M27: =M26+2*(L26/$B$20)*J27 -> 1907.5543 | N27: =SQRT(M27) -> 43.675557 | O27: =0.5*$B$2*M27 -> 2.268082 | P27: =O27*$B$16*$B$19 -> 1701.0615 | Q27: =O27*$B$16*$B$21 -> 375.632 | R27: =$B$7*($B$1-O27) -> 101.39464 | S27: =0.592*N27 -> 25.85593 | U27: =V27*(J27/N27) -> -0.28509111 | V27: =W26*(J27/N27) -> -2.4903026 | W27: =(P27-$B$1)/$B$20 -> -21.383394
J28: 5 | K28: 130 | L28: =$B$10+$B$11-Q28-R28 -> 1004.64 | M28: =M27+2*(L27/$B$20)*J28 -> 1972.0892 | N28: =SQRT(M28) -> 44.408211 | O28: =0.5*$B$2*M28 -> 2.3448141 | P28: =O28*$B$16*$B$19 -> 1758.6105 | Q28: =O28*$B$16*$B$21 -> 388.3401 | R28: =$B$7*($B$1-O28) -> 101.3931 | S28: =0.592*N28 -> 26.289661 | U28: =V28*(J28/N28) -> -0.27107539 | V28: =W27*(J28/N28) -> -2.4075946 | W28: =(P28-$B$1)/$B$20 -> -21.018334
J29: 5 | K29: 135 | L29: =$B$10+$B$11-Q29-R29 -> 992.09212 | M29: =M28+2*(L28/$B$20)*J29 -> 2035.8181 | N29: =SQRT(M29) -> 45.120041 | O29: =0.5*$B$2*M29 -> 2.4205877 | P29: =O29*$B$16*$B$19 -> 1815.4408 | Q29: =O29*$B$16*$B$21 -> 400.88947 | R29: =$B$7*($B$1-O29) -> 101.39159 | S29: =0.592*N29 -> 26.711064 | U29: =V29*(J29/N29) -> -0.25810674 | V29: =W28*(J29/N29) -> -2.3291573 | W29: =(P29-$B$1)/$B$20 -> -20.657835
J30: 5 | K30: 140 | L30: =$B$10+$B$11-Q30-R30 -> 979.70099 | M30: =M29+2*(L29/$B$20)*J30 -> 2098.751 | N30: =SQRT(M30) -> 45.812127 | O30: =0.5*$B$2*M30 -> 2.4954149 | P30: =O30*$B$16*$B$19 -> 1871.5612 | Q30: =O30*$B$16*$B$21 -> 413.2821 | R30: =$B$7*($B$1-O30) -> 101.39009 | S30: =0.592*N30 -> 27.120779 | U30: =V30*(J30/N30) -> -0.24607296 | V30: =W29*(J30/N30) -> -2.2546251 | W30: =(P30-$B$1)/$B$20 -> -20.301837
J31: 5 | K31: 145 | L31: =$B$10+$B$11-Q31-R31 -> 967.46462 | M31: =M30+2*(L30/$B$20)*J31 -> 2160.8979 | N31: =SQRT(M31) -> 46.485459 | O31: =0.5*$B$2*M31 -> 2.5693076 | P31: =O31*$B$16*$B$19 -> 1926.9807 | Q31: =O31*$B$16*$B$21 -> 425.51995 | R31: =$B$7*($B$1-O31) -> 101.38861 | S31: =0.592*N31 -> 27.519392 | U31: =V31*(J31/N31) -> -0.23487733 | V31: =W30*(J31/N31) -> -2.1836761 | W31: =(P31-$B$1)/$B$20 -> -19.950286
J32: 5 | K32: 150 | L32: =$B$10+$B$11-Q32-R32 -> 955.38108 | M32: =M31+2*(L31/$B$20)*J32 -> 2222.2685 | N32: =SQRT(M32) -> 47.140943 | O32: =0.5*$B$2*M32 -> 2.6422773 | P32: =O32*$B$16*$B$19 -> 1981.708 | Q32: =O32*$B$16*$B$21 -> 437.60494 | R32: =$B$7*($B$1-O32) -> 101.38715 | S32: =0.592*N32 -> 27.907438 | U32: =V32*(J32/N32) -> -0.22443604 | V32: =W31*(J32/N32) -> -2.1160254 | W32: =(P32-$B$1)/$B$20 -> -19.603126
J33: 5 | K33: 155 | L33: =$B$10+$B$11-Q33-R33 -> 943.44846 | M33: =M32+2*(L32/$B$20)*J33 -> 2282.8727 | N33: =SQRT(M33) -> 47.779417 | O33: =0.5*$B$2*M33 -> 2.7143356 | P33: =O33*$B$16*$B$19 -> 2035.7517 | Q33: =O33*$B$16*$B$21 -> 449.539 | R33: =$B$7*($B$1-O33) -> 101.38571 | S33: =0.592*N33 -> 28.285415 | U33: =V33*(J33/N33) -> -0.21467608 | V33: =W32*(J33/N33) -> -2.0514196 | W33: =(P33-$B$1)/$B$20 -> -19.260302
... J62: 5 | K62: 300 | L62: =$B$10+$B$11-Q62-R62 -> 655.27408 | M62: =M61+2*(L61/$B$20)*J62 -> 3746.4718 | N62: =SQRT(M62) -> 61.208429 | O62: =0.5*$B$2*M62 -> 4.454555 | P62: =O62*$B$16*$B$19 -> 3340.9162 | Q62: =O62*$B$16*$B$21 -> 737.74819 | R62: =$B$7*($B$1-O62) -> 101.35091 | S62: =0.592*N62 -> 36.23539 | U62: =V62*(J62/N62) -> -0.074864835 | V62: =W61*(J62/N62) -> -0.9164718 | W62: =(P62-$B$1)/$B$20 -> -10.981051
J63: 5 | K63: 305 | L63: =$B$10-Q63-R63 -> 34654.067 | M63: =M62+2*(L62/$B$20)*J63 -> 3788.0388 | N63: =SQRT(M63) -> 61.547046 | O63: =0.5*$B$2*M63 -> 4.5039782 | P63: =O63*$B$16*$B$19 -> 3377.9836 | Q63: =O63*$B$16*$B$21 -> 745.93349 | R63: 0 | S63: =0.592*N63 -> 36.435851 | U63: =V63*(J63/N63) -> -0.072471872 | V63: =W62*(J63/N63) -> -0.89208592 | W63: =(P63-$B$1)/$B$20 -> -10.745915
J64: 5 | K64: 310 | L64: =$B$10-Q64-R64 -> 34221.188 | M64: =M63+2*(L63/$B$20)*J64 -> 5986.3037 | N64: =SQRT(M64) -> 77.371207 | O64: =0.5*$B$2*M64 -> 7.1177151 | P64: =O64*$B$16*$B$19 -> 5338.2863 | Q64: =O64*$B$16*$B$21 -> 1178.8117 | R64: 0 | S64: =0.592*N64 -> 45.803755 | U64: =V64*(J64/N64) -> -0.044877089 | V64: =W63*(J64/N64) -> -0.69443891 | W64: =(P64-$B$1)/$B$20 -> 1.6891751
J65: 5 | K65: 315 | L65: =$B$10-Q65-R65 -> 33793.717 | M65: =M64+2*(L64/$B$20)*J65 -> 8157.1091 | N65: =SQRT(M65) -> 90.316716 | O65: =0.5*$B$2*M65 -> 9.6988027 | P65: =O65*$B$16*$B$19 -> 7274.1021 | Q65: =O65*$B$16*$B$21 -> 1606.2826 | R65: 0 | S65: =0.592*N65 -> 53.467496 | U65: =V65*(J65/N65) -> 0.0051770028 | V65: =W64*(J65/N65) -> 0.093513977 | W65: =(P65-$B$1)/$B$20 -> 13.968934
J66: 5 | K66: 320 | L66: =$B$10-Q66-R66 -> 33371.586 | M66: =M65+2*(L65/$B$20)*J66 -> 10300.798 | N66: =SQRT(M66) -> 101.49285 | O66: =0.5*$B$2*M66 -> 12.247649 | P66: =O66*$B$16*$B$19 -> 9185.7367 | Q66: =O66*$B$16*$B$21 -> 2028.4138 | R66: 0 | S66: =0.592*N66 -> 60.083766 | U66: =V66*(J66/N66) -> 0.033902552 | V66: =W65*(J66/N66) -> 0.6881733 | W66: =(P66-$B$1)/$B$20 -> 26.095301
J67: 5 | K67: 325 | L67: =$B$10-Q67-R67 -> 32954.728 | M67: =M66+2*(L66/$B$20)*J67 -> 12417.709 | N67: =SQRT(M67) -> 111.43478 | O67: =0.5*$B$2*M67 -> 14.764657 | P67: =O67*$B$16*$B$19 -> 11073.492 | Q67: =O67*$B$16*$B$21 -> 2445.272 | R67: 0 | S67: =0.592*N67 -> 65.969388 | U67: =V67*(J67/N67) -> 0.052536462 | V67: =W66*(J67/N67) -> 1.1708778 | W67: =(P67-$B$1)/$B$20 -> 38.070192
J68: 5 | K68: 330 | L68: =$B$10-Q68-R68 -> 32543.077 | M68: =M67+2*(L67/$B$20)*J68 -> 14508.178 | N68: =SQRT(M68) -> 120.4499 | O68: =0.5*$B$2*M68 -> 17.250223 | P68: =O68*$B$16*$B$19 -> 12937.667 | Q68: =O68*$B$16*$B$21 -> 2856.923 | R68: 0 | S68: =0.592*N68 -> 71.306339 | U68: =V68*(J68/N68) -> 0.065601266 | V68: =W67*(J68/N68) -> 1.5803331 | W68: =(P68-$B$1)/$B$20 -> 49.895501
...

Sheet LandingCalculator
A1: Min Landing | J1: AIAA Limit | K1: 145 knots
A2: Value | E2: Outputs | F2: ft/s | G2: knots | J2: Min Weight | K2: =G4 -> 124.87883
A3: CL | B3: 0.9 | E3: Vstall | F3: =SQRT((2*B4)/(B5*B6*B3)) -> 191.61059 | G3: =F3*0.592484 -> 113.52621 | J3: AIAA | K3: =G11 -> 144.03033
A4: weight | B4: 22205 | E4: Vapp | F4: =1.1*F3 -> 210.77164 | G4: =F4*0.592484 -> 124.87883 | J4: Max Landing | K4: =G18 -> 172.90197
A5: density | B5: 0.00224 | E5: Veng | F5: =1.05*F4 -> 221.31023 | G5: =F5*0.592484 -> 131.12277
A6: wing area | B6: 600
A8: AIAA Landing
A9: Value | E9: Outputs | F9: ft/s | G9: knots
A10: CL | B10: 0.9 | E10: Vstall | F10: =SQRT((2*B11)/(B12*B13*B10)) -> 220.99612 | G10: =F10*0.592484 -> 130.93667
A11: weight | B11: 29538 | E11: Vapp | F11: =1.1*F10 -> 243.09573 | G11: =F11*0.592484 -> 144.03033
A12: density | B12: 0.00224 | E12: Veng | F12: =1.05*F11 -> 255.25052 | G12: =F12*0.592484 -> 151.23185
A13: wing area | B13: 600
A15: Max Landing
A16: Value | E16: Outputs | F16: ft/s | G16: knots
A17: CL | B17: 0.9 | E17: Vstall | F17: =SQRT((2*B18)/(B19*B20*B17)) -> 265.29596 | G17: =F17*0.592484 -> 157.18361
A18: weight | B18: 42567 | E18: Vapp | F18: =1.1*F17 -> 291.82555 | G18: =F18*0.592484 -> 172.90197
A19: density | B19: 0.00224 | E19: Veng | F19: =1.05*F18 -> 306.41683 | G19: =F19*0.592484 -> 181.54707
A20: wing area | B20: 600

Sheet Life Cycle Cost 
A2: 62% of Empty Weight | B2: W | C2: 16043.23 | D2: (lbs)
A3: Maximum Speed (Guess) | B3: Q | C3: 1333.48 | D3: (kn) | J3: Total Cost Of Program (500 Aircraft) | N3: Total Cost Of Program (1 Aircraft)
A4: Quantity of Aircraft Produceed | B4: S | C4: 500 | J4: Airframe Engineering | K4: $ | L4: =G9 -> 19374588 | N4: Airframe Engineering | O4: $ | P4: =L4/500 -> 38749.177
A5: Sea Level Max Thrust | B5: T_SLS | C5: 22000 | D5: (lbf) | J5: Development Support | K5: $ | L5: =C10 -> 1.8896956e+08 | N5: Development Support | O5: $ | P5: =L5/500 -> 377939.13
A6: Turbine Inlet Temperature (Guess) | B6: T_R | C6: 3000 | D6: (R) | J6: Flight Test Operations | K6: $ | L6: =C11 -> 99430803 | N6: Flight Test Operations | O6: $ | P6: =L6/500 -> 198861.61
A7: Maximum Mach Number (Guess) | B7: M_Max | C7: 2 | J7: Tooling | K7: $ | L7: =G12 -> 16031875 | N7: Tooling | O7: $ | P7: =L7/500 -> 32063.75
J8: Manufacturing | K8: $ | L8: =G13 -> 97710881 | N8: Manufacturing | O8: $ | P8: =L8/500 -> 195421.76
A9: Airframe Engineering | B9: E | C9: =4.86*(C2^0.777)*(C4^0.894)*(C3^0.163) -> 7523154.7 | D9: Hours | F9: Engineering Rate$ | G9: =2.576*C9-5058 -> 19374588 | H9: 2025 $ | J9: Quality Control | K9: $ | L9: =G14+G15 -> 22587525 | N9: Quality Control | O9: $ | P9: =L9/500 -> 45175.049
A10: Development Support | B10: D | C10: =66*(C2^0.63)*(C4^1.3)*1.99 -> 1.8896956e+08 | D10: 2025 $ | J10: Total Cost Of Materials | K10: $ | L10: =C16 -> 3.6260215e+09 | N10: Total Cost Of Materials | O10: $ | P10: =L10/500 -> 7252043.1
A11: Flight Test Operations (Q_D=5) | B11: F | C11: =1852*(C2^0.325)*(C4^0.822)*(5^1.21)*1.99 -> 99430803 | D11: 2025 $ | J11: Engine and Avionics | K11: $ | L11: =C17 -> 9690005.7 | N11: Engine and Avionics | O11: $ | P11: =L11/500 -> 19380.011
A12: Tooling | B12: T | C12: =5.99*(C2^0.777)*(C4^0.696)*(C3^0.263) -> 5562796 | D12: Hours | F12: Tooling Rate$ | G12: =2.883*C12-5666 -> 16031875 | H12: 2025 $ | J12: Test Facilities | K12: $ | N12: Test Facilities | O12: $
A13: Manufacturing Labor | B13: L | C13: =7.37*(C2^0.82)*(C4^0.484)*(C3^0.641) -> 42191465 | D13: Hours | F13: Manufacturing Rate$ | G13: =2.316*C13-4552 -> 97710881 | H13: 2025 $ | J13: Sustaining Engineering | K13: $ | N13: Sustaining Engineering | O13: $
A14: Quality Control | B14: QC | C14: =0.076*C13 -> 3206551.3 | D14: Hours (Cargo) | F14: QC Cargo Rate$ | G14: =2.6*C14-5112 -> 8331921.5 | H14: 2025 $ | J14: Total Program Cost | K14: $ | L14: =SUM(L4:L13) -> 4.0798168e+09 | N14: Total Program Cost | O14: $ | P14: =L14/500 -> 8159633.5
B15: QC | C15: =0.13*C13 -> 5484890.4 | D15: Hours (Other Aircraft) | F15: QC Aircraft Rate$ | G15: =2.6*C15-5112 -> 14255603 | H15: 2025 $
A16: Manufacutring Material Equipment | B16: M | C16: =16.39*(C2^0.921)*(C4^0.621)*(C3^0.799)*1.99 -> 3.6260215e+09 | D16: 2025 $
A17: Engine and Avionics | B17: P | C17: =2306*(0.043*C5+243.3*C7+0.969*C6-2228)*1.99 -> 9690005.7 | D17: 2025 $
A19: Price Fuel | B19: 0.95 | C19: ($/lb) | F19: Flight Hours Annual | G19: 500 | H19: (hrs)
A20: k | B20: 0.147858 | F20: Maintenance Man Hours | G20: =G19*18 -> 9000 | H20: (hrs)
A21: C_DO | B21: 0.045 | F21: Hours Per Crew Member | G21: =G19*1.1 -> 550 | H21: (hrs)
A22: 1/2 ro v^2 S | B22: =0.5*(0.000891)*(843.9^2)*406.6773 -> 129026.71
A23: C_L at Cruise | B23: =51752.35702/B22 -> 0.40109802 | F23: Flight Hours Lifetime | G23: =G19*25 -> 12500 | H23: (hrs)
A24: C_D at Cruise | B24: =B21+B20*B23^2 -> 0.068787339 | F24: Maintenance Man Hours | G24: =G23*18 -> 225000 | H24: (hrs)
A25: D | B25: =B22*B24 -> 8875.4039 | C25: (lbf) | F25: Hours Per Crew Member | G25: =G23*1.1 -> 13750 | H25: (hrs)
A26: TSFC | B26: 0.8 | C26: lb/lbf*hr
A27: Fuel Flow | B27: =B25*B26 -> 7100.3231 | C27: lb/hr | F27: Crew Cost (225$/hr) Year | G27: =225*G21 -> 123750 | H27: 2025 $
A28: Fuel Cost (500hr) | B28: =500*B27*B19 -> 3372653.5 | C28: 2025 $ | F28: Crew Cost (225$/hr) Lifetime | G28: 3093750 | H28: 2025 $
A29: Fuel Cost (12500hr) | B29: =12500*B27*B19 -> 84316337 | C29: 2025 $

Sheet Lat.-Dir. Stability
A1: Taper Ratio, V | B1: 0.3
A2: Taper Ratio, W | B2: 0.5
A3: Zv (in)/(ft) | B3: 72 | C3: 6
A4: b (ft) | B4: 45
A5: 2Zv/b | B5: 0.26666667
A6: LE Sweep, Λ | B6: 20
A7: 1/4 chord sweep, Λ c/4 | B7: 17
A8: Aspect Ratio,W | B8: 4.43
A9: Angle of attack, α | B9: 5
A10: Dihedral | B10: 0
A11: Wing Area, S (ft^2) | B11: 457
A12: Exposed wing area (S,exp (ft^2)) | B12: 300 | C12: Estimate
A13: bv (ft) | B13: 12
A14: Fuselage avereage depth in the region of vert tail, 2r1 (ft) | B14: 4.5 | C14: Estimate range 3-6.5 ft
A15: Horizontail Tail Area (St (ft)) | B15: 110
A16: Vertical Tail Area (Sv (ft)) | B16: 130
A17: Aspect Ratio Vert Tail, Av | B17: 2.2153846
A18: Velocity (M) | B18: 0.3 | C18: Estimate
A19: Velocity (u0) | B19: 31.364 | C19: ft/s
A20: density sea level, ρ0 | B20: 0.002377 | C20: slug/ft^3
A21: density cruise altitude, ρ
A23: σβα | B23: -0.01 | C23: Estimate from Pamadi (pg 451)
A24: σβГ | B24: -0.6 | C24: Estimate from Pamadi (pg 452)
A25: σβ,WB | B25: 0.06 | C25: Estimate from Pamadi (pg 453)
A27: σβ | B27: 0.01
A29: Fuselage length (lf (ft)) | B29: 40 | C29: Estimate
A30: Max diameter (bf,max (ft)) | B30: 7 | C30: Estimate
A31: Fineness ratio (lf/bf,max) | B31: 5.7142857
A32: k2-k1 | B32: 0.85 | C32: Estimate from Pamadi (pg 183)
A33: Max cross sectional area of fuselage (Sb,max (ft^2)) | B33: 38.48451
A34: bf, max/b | B34: 0.15555556
A36: Lift-curve slope, nose (CLα,N) | B36: 0.14315901 | C36: [2*(k2-k1)*Sb,max]/S
A37: Lift-curve slope, exposed wing (CLα,e) | B37: 0.04 | C37: Estimate range 0.03-0.06
A39: KN | B39: 5.4519723 | C39: KN = (CLα,N/CLα,e)*(S/S,exp)
A40: KW(B) | B40: 1.131063 | C40: Eqn from Pamadi (pg 198)
A41: KB(W) | B41: 0.21399161 | C41: Eqn from Pamadi (pg 198)
A43: CLα,WB (a0) | B43: 0.17847773 | C43: (KN +KW(B) + KB(W))*CLα,e*(S,exp/S) | D43: Pamadi pg 196
A44: bv/2r1 | B44: 2.6666667
A45: AV(B)/AV | B45: 1.46 | C45: Estimate from Pamadi (pg 294)
A46: zv/bv | B46: 0.5
...
